
````java
public class TryCatchFinallyExample {
    public static void main(String[] args) {

        try {
            Class clazz = Class.forName("java.lang.String2");
        } catch (ClassNotFoundException e) {
            e.printStackTrace();
            System.out.println("클래스가 존재하지 않습니다.");
        }
    }
}

````

java.lang.String2 클래스가 존재하지 않기 때문에
ClassNotFountException 이 발생한다.
그렇기 때문에 catch()~ 이후에 코드가 실행된다.

ArrayIndexOutOfBoundsException이나 , NumberFormatException 과 같은
실행예외는 컴파일러가 예외 처리 코드를 체크하지 않기 때문에 인텔리제이에서도
빨간 밑줄이 생기지 않는다. 오로지 개발자의 경험에 의해 예외 처리를
다음과 같이 작생해줘야한다.

```java
public class TryCatchFinallyRuntimeExceptionExample {
    public static void main(String[] args) {
        String data1 = null;
        String data2 = null;

        try {
            
            data1 = args[0];
            data2 = args[1];

        } catch (ArrayIndexOutOfBoundsException e) {
            System.out.println("실행 매개값의 수가 부족합니다");
            System.out.println("[실행 방법]");
            System.out.println("java TryCatchFinallyRuntimeExceptionExample num1 num2");
            return;

        }

        try {
            int value1 = Integer.parseInt(data1);
            int value2= Integer.parseInt(data2);
            int result = value1 + value2;
            System.out.println(value1 + " + " + value2 + " = " + result);
        
        } catch (NumberFormatException e) {
            System.out.println("숫자로 변환할 수 없습니다.");

        }finally {
            System.out.println("다시 실행하세요");
        }
    }
}
```